try {
	let s = 3;
	throw("exception");
} catch (e) {
	print("Hello");
}

print("Done");
